<?xml version="1.0" ?>
<robot name="robot" xmlns:xacro="http://www.ros.org/wiki/xacro">
  <!-- Arguments and Defaults-->
  <gazebo>
    <plugin filename="libgazebo_ros_control.so" name="ros_control">
      <robotNamespace>/robot</robotNamespace>
    </plugin>
  </gazebo>  
  <xacro:arg name="gazebo" default="false"/>
  <link name="quickie">
    <visual>
      <origin rpy="1.5708 0 1.5708" xyz="0 0 -0.5575"/>
      <geometry>
        <mesh filename="package://baxter_description/meshes/quickie/No_Wheel_Quickie.stl" scale="0.001 0.001 0.001"/>
      </geometry>
      <material name="darkgray">
        <color rgba=".2 .2 .2 1"/>
      </material>
    </visual>
    <collision>
      <origin rpy="1.5708 0 1.5708" xyz="0 0 -0.36"/>
      <geometry>
        <box size="0.6 0.5 0.83" />
      </geometry>
    </collision>
    <inertial>
      <origin rpy="1.5708 0 1.5708" xyz="0 0 -0.38"/>
      <mass value="130" />
      <inertia  ixx="11.233" ixy="0.0"  ixz="0.0"  iyy="10.83"  iyz="0.0"  izz="8.199" />
    </inertial>
  </link>


  <link name = "bottom_right_holder">
  	 <visual>
  	 	 <origin rpy="0 0 0" xyz="0 0 0"/>
  	 	 <geometry>
        <mesh filename="package://baxter_description/meshes/quickie/Bottom_Right_Holder.stl" scale="0.001 0.001 0.001"/>
      </geometry>
      <material name="darkgray">
        <color rgba=".2 .2 .2 1"/>
      </material>
    </visual>
   <collision>
       <origin rpy="0 0 0" xyz="0 0 0"/>
      <geometry>
        <mesh filename="package://baxter_description/meshes/quickie/Bottom_Right_Holder.stl" scale="0.001 0.001 0.001"/>
      </geometry>
   </collision>
   <inertial>
      <origin rpy="0 0 0" xyz="0 0 0"/>
      <mass value="0.5" />
      <inertia  ixx="0.000254" ixy="0.0"  ixz="0.0"  iyy="0.000254"  iyz="0.0"  izz="0.001" />
    </inertial>
  </link>


 <link name = "bottom_left_holder">
  	 <visual>
  	 	 <origin rpy="0 0 0" xyz="0 0 0"/>
  	 	 <geometry>
        <mesh filename="package://baxter_description/meshes/quickie/Bottom_Left_Holder.stl" scale="0.001 0.001 0.001"/>
      </geometry>
      <material name="darkgray">
        <color rgba=".2 .2 .2 1"/>
      </material>
    </visual>
       <collision>
       <origin rpy="0 0 0" xyz="0 0 0"/>
      <geometry>
        <mesh filename="package://baxter_description/meshes/quickie/Bottom_Left_Holder.stl" scale="0.001 0.001 0.001"/>
      </geometry>
   </collision>
   <inertial>
      <origin rpy="0 0 0" xyz="0 0 0"/>
      <mass value="0.5" />
      <inertia  ixx="0.000254" ixy="0.0"  ixz="0.0"  iyy="0.000254"  iyz="0.0"  izz="0.001" />
    </inertial>
      </link>

 <link name = "top_left_holder">
  	 <visual>
  	 	 <origin rpy="0 0 0" xyz="0 0 0"/>
  	 	 <geometry>
        <mesh filename="package://baxter_description/meshes/quickie/Top_Left_Holder.stl" scale="0.001 0.001 0.001"/>
      </geometry>
      <material name="darkgray">
        <color rgba=".2 .2 .2 1"/>
      </material>
    </visual>
        <mesh filename="package://baxter_description/meshes/quickie/Top_Left_Holder.stl" scale="0.001 0.001 0.001"/>   
    <inertial>
      <origin rpy="0 0 0" xyz="0 0 0"/>
      <mass value="0.5" />
      <inertia  ixx="0.000254" ixy="0.0"  ixz="0.0"  iyy="0.000254"  iyz="0.0"  izz="0.001" />
    </inertial>
      </link>    

 <link name = "top_right_holder">
  	 <visual>
  	 	 <origin rpy="0 0 0" xyz="0 0 0"/>
  	 	 <geometry>
        <mesh filename="package://baxter_description/meshes/quickie/Top_Right_Holder.stl" scale="0.001 0.001 0.001"/>
      </geometry>
      <material name="darkgray">
        <color rgba=".2 .2 .2 1"/>
      </material>
    </visual>
       <geometry>
        <mesh filename="package://baxter_description/meshes/quickie/Top_Right_Holder.stl" scale="0.001 0.001 0.001"/>
      </geometry>    
   <inertial>
      <origin rpy="0 0 0" xyz="0 0 0"/>
      <mass value="0.5" />
      <inertia  ixx="0.000254" ixy="0.0"  ixz="0.0"  iyy="0.000254"  iyz="0.0"  izz="0.001" />
    </inertial>
      </link>   


  <link name = "small_bottom_right_wheel">
  	 <visual>
  	 	 <origin rpy="0 0 0" xyz="0 0 0"/>
  	 	 <geometry>
        <mesh filename="package://baxter_description/meshes/quickie/Small_Bottom_Right.stl" scale="0.001 0.001 0.001"/>
      </geometry>
      <material name="darkgray">
        <color rgba=".2 .2 .2 1"/>
      </material>
    </visual>
   <collision>
      <origin rpy="1.57079632679 0 0" xyz="0 0 0"/>
      <geometry>
        <cylinder length="0.06" radius="0.075"/>
      </geometry>
    </collision>
    <surface>
        <friction>
          <ode>
            <mu>1000000000</mu>
            <mu2>1000000000</mu2>
            <fdir1>0 0 1</fdir1>
            <slip1>0.0</slip1>
            <slip2>0.0</slip2>
          </ode>
        </friction>
      </surface>
    <inertial>
      <origin rpy="0 0 0" xyz="0 0 0"/>
      <mass value="0.7" />
      <inertia  ixx="0.001895" ixy="0.0"  ixz="0.0"  iyy="0.0035"  iyz="0.0"  izz="0.001895" />
    </inertial>
      </link>
  <link name = "small_bottom_left_wheel">
  	 <visual>
  	 	 <origin rpy="0 0 0" xyz="0 0 0"/>
  	 	 <geometry>
        <mesh filename="package://baxter_description/meshes/quickie/Small_Bottom_Left.stl" scale="0.001 0.001 0.001"/>
      </geometry>
      <material name="darkgray">
        <color rgba=".2 .2 .2 1"/>
      </material>
    </visual>
   <collision>
      <origin rpy="1.57079632679 0 0" xyz="0 0 0"/>
      <geometry>
        <cylinder length="0.06" radius="0.075"/>
      </geometry>
      <surface>
        <friction>
          <ode>
            <mu>1000000000</mu>
            <mu2>1000000000</mu2>
            <fdir1>0 0 1</fdir1>
            <slip1>0.0</slip1>
            <slip2>0.0</slip2>
          </ode>
        </friction>
      </surface>
    </collision>
    <inertial>
      <origin rpy="0 0 0" xyz="0 0 0"/>
        <mass value="0.7" />
      <inertia  ixx="0.001895" ixy="0.0"  ixz="0.0"  iyy="0.0035"  iyz="0.0"  izz="0.001895" />
    </inertial>
      </link>
  <link name = "small_top_right_wheel">
  	 <visual>
  	 	 <origin rpy="0 0 0" xyz="0 0 0"/>
  	 	 <geometry>
        <mesh filename="package://baxter_description/meshes/quickie/Small_Top_Right.stl" scale="0.001 0.001 0.001"/>
      </geometry>
      <material name="darkgray">
        <color rgba=".2 .2 .2 1"/>
      </material>
    </visual>
   <collision>
      <origin rpy="1.57079632679 0 0" xyz="0 0 0"/>
      <geometry>
        <cylinder length="0.06" radius="0.085"/>
      </geometry>
      <surface>
        <friction>
          <ode>
            <mu>1000000000</mu>
            <mu2>1000000000</mu2>
            <fdir1>0 0 1</fdir1>
            <slip1>0.0</slip1>
            <slip2>0.0</slip2>
          </ode>
        </friction>
      </surface>
    </collision>
    <inertial>
      <origin rpy="0 0 0" xyz="0 0 0"/>
      <mass value="0.7" />
      <inertia  ixx="0.001895" ixy="0.0"  ixz="0.0"  iyy="0.0035"  iyz="0.0"  izz="0.001895" />
    </inertial>
  </link>  
  <link name = "small_top_left_wheel">
  	 <visual>
  	 	 <origin rpy="0 0 0" xyz="0 0 0"/>
  	 	 <geometry>
        <mesh filename="package://baxter_description/meshes/quickie/Small_Top_Left.stl" scale="0.001 0.001 0.001"/>
      </geometry>
      <material name="darkgray">
        <color rgba=".2 .2 .2 1"/>
      </material>
    </visual>
   <collision>
      <origin rpy="1.57079632679 0 0" xyz="0 0 0"/>
      <geometry>
        <cylinder length="0.06" radius="0.085"/>
      </geometry>
      <surface>
        <friction>
          <ode>
            <mu>1000000000</mu>
            <mu2>1000000000</mu2>
            <fdir1>0 0 1</fdir1>
            <slip1>0.0</slip1>
            <slip2>0.0</slip2>
          </ode>
        </friction>
      </surface>
    </collision>
    <inertial>
      <origin rpy="0 0 0" xyz="0 0 0"/>
      <mass value="0.7" />
      <inertia  ixx="0.001895" ixy="0.0"  ixz="0.0"  iyy="0.0035"  iyz="0.0"  izz="0.001895" />
    </inertial>
</link>

        <link name = "large_right_wheel">
  	 <visual>
  	 	 <origin rpy="0 0 0" xyz="0 0 0"/>
  	 	 <geometry>
        <mesh filename="package://baxter_description/meshes/quickie/Large_Right.stl" scale="0.001 0.001 0.001"/>
      </geometry>
      <material name="darkgray">
        <color rgba=".2 .2 .2 1"/>
      </material>
    </visual>
   <collision>
      <origin rpy="1.57079632679 0 0" xyz="0 0 0"/>
      <geometry>
        <cylinder length="0.06" radius="0.165"/>
      </geometry>
      <surface>
        <friction>
          <ode>
            <mu>1000000000</mu>
            <mu2>1000000000</mu2>
            <fdir1>0 0 1</fdir1>
            <slip1>0.0</slip1>
            <slip2>0.0</slip2>
          </ode>
        </friction>
      </surface>
    </collision> 
    <inertial>
      <origin rpy="0 0 0" xyz="0 0 0"/>
      <mass value="3.5" />
      <inertia  ixx="0.02345" ixy="0.0"  ixz="0.0"  iyy="0.0448"  iyz="0.0"  izz="0.02345" />
    </inertial>
      </link> 
        <link name = "large_left_wheel">
  	 <visual>
  	 	 <origin rpy="0 0 0" xyz="0 0 0"/>
  	 	 <geometry>
        <mesh filename="package://baxter_description/meshes/quickie/Large_Left.stl" scale="0.001 0.001 0.001"/>
      </geometry>
      <material name="darkgray">
        <color rgba=".2 .2 .2 1"/>
      </material>
    </visual>
   <collision>
      <origin rpy="1.57079632679 0 0" xyz="0 0 0"/>
      <geometry>
        <cylinder length="0.06" radius="0.165"/>
      </geometry>
      <surface>
        <friction>
          <ode>
            <mu>1000</mu>
            <mu2>1000</mu2>
            <fdir1>0 0 1</fdir1>
            <slip1>0.0</slip1>
            <slip2>0.0</slip2>
          </ode>
        </friction>
      </surface>
    </collision>
   <inertial>
      <origin rpy="0 0 0" xyz="0 0 0"/>
     <mass value="3.5" />
      <inertia  ixx="0.02345" ixy="0.0"  ixz="0.0"  iyy="0.0448"  iyz="0.0"  izz="0.02345" />
    </inertial>
  </link> 
  <joint name="quickie_fixed" type="fixed">
    <origin rpy="0 0 0" xyz="0.0 0.0 0"/>
    <parent link="base"/>
    <child link="quickie"/>
  </joint>
  <joint name="bottom_right_holder_joint" type="continuous">
    <origin rpy="0 0 3.1415" xyz="-0.392 -0.2 -0.4615"/>
    <parent link="quickie"/>
    <child link="bottom_right_holder"/>
    <dynamics damping="1.0" friction="10.0"/>
    <axis xyz="0 0 1"/>
  </joint>
  <joint name="bottom_left_holder_joint" type="continuous">
    <origin rpy="0 0 3.1415" xyz="-0.392 0.2 -0.465"/>
    <parent link="quickie"/>
    <child link="bottom_left_holder"/>
    <dynamics damping="1.0" friction="10.0"/>
    <axis xyz="0 0 1"/>
  </joint>   
  <joint name="top_right_holder_joint" type="continuous">
    <origin rpy="0 0 0" xyz="0.3 -0.25 -0.445"/>
    <parent link="quickie"/>
    <child link="top_right_holder"/>
    <dynamics damping="1.0" friction="10.0"/>
    <axis xyz="0 0 1"/>
  </joint>
  <joint name="top_left_holder_joint" type="continuous">
    <origin rpy="0 0 0" xyz="0.3 0.25 -0.445"/>
    <parent link="quickie"/>
    <child link="top_left_holder"/>
    <dynamics damping="1.0" friction="10.0"/>
    <axis xyz="0 0 1"/>
  </joint>    
   <joint name="small_bottom_right_wheel_joint" type="fixed">
    <origin rpy="0 0 0" xyz="0.045 0 -0.1"/>
    <parent link="bottom_right_holder"/>
    <child link="small_bottom_right_wheel"/>
    <dynamics damping="1.0" friction="10000000.0"/>
    <axis xyz="0 1 0"/>
  </joint>
   <joint name="small_bottom_left_wheel_joint" type="fixed">
    <origin rpy="0 0 0" xyz="0.045 0 -0.1"/>
    <parent link="bottom_left_holder"/>
    <child link="small_bottom_left_wheel"/>
    <dynamics damping="1.0" friction="10000000.0"/>
    <axis xyz="0 1 0"/>
  </joint>  
   <joint name="small_top_right_wheel_joint" type="fixed">
    <origin rpy="0 0 0" xyz="0.05 0 -0.1"/>
    <parent link="top_right_holder"/>
    <child link="small_top_right_wheel"/>
    <axis xyz="0 1 0"/>
  </joint> 
   <joint name="small_top_left_wheel_joint" type="fixed">
    <origin rpy="0 0 0" xyz="0.05 0 -0.1"/>
    <parent link="top_left_holder"/>
    <child link="small_top_left_wheel"/>
    <dynamics damping="1.0" friction="10000000.0"/>
    <axis xyz="0 1 0"/>
  </joint>    
  <joint name="large_right_wheel_joint" type="continuous">
    <origin rpy="0 0 0" xyz="-0.02 -0.27 -0.47"/>
    <parent link="quickie"/>
    <child link="large_right_wheel"/>
    <axis xyz="0 1 0"/>
    <dynamics damping="0.01" friction="10000000.1"/>
  </joint>
  <joint name="large_left_wheel_joint" type="continuous">
    <origin rpy="0 0 0" xyz="-0.02 0.27 -0.47"/>
    <parent link="quickie"/>
    <child link="large_left_wheel"/>
    <axis xyz="0 1 0"/>
    <dynamics damping="0.01" friction="10000000.1"/>
  </joint>

  <gazebo reference="quickie">
    <material>Gazebo/DarkGrey</material>
  </gazebo>
  <gazebo reference="Small_Top_Right" >
    <kd value="2"/>
    <kp value="10"/>
  </gazebo> 
  <gazebo reference="Small_Top_Left" >
    <kd value="2"/>
    <kp value="10"/>
  </gazebo> 
  <gazebo reference="Small_Bottom_Right" >
    <kd value="2"/>
    <kp value="10"/>
  </gazebo> 
  <gazebo reference="Small_Bottom_Left" >
    <kd value="2"/>
    <kp value="10"/>
  </gazebo> 
  <gazebo reference="Large_Right" >
    <kd value="2"/>
    <kp value="10"/>
  </gazebo> 
  <gazebo reference="Large_Left" >
    <kd value="2"/>
    <kp value="10"/>
  </gazebo> 

  <gazebo>
    <plugin name="differential_drive_controller" filename="libgazebo_ros_diff_drive.so">
      <alwaysOn>true</alwaysOn>
      <updateRate>20</updateRate>
      <leftJoint>large_left_wheel_joint</leftJoint>
      <rightJoint>large_right_wheel_joint</rightJoint>
      <wheelSeparation>0.2030</wheelSeparation>
      <wheelDiameter>0.350</wheelDiameter>
      <torque>20</torque>
      <legacyMode>true</legacyMode>
      <commandTopic>quickie/diff_drive/command</commandTopic>
      <odometryTopic>odom</odometryTopic>
      <odometryFrame>odom</odometryFrame>
      <robotBaseFrame>base</robotBaseFrame>
      <robotNamespace>robot</robotNamespace> 
    </plugin>
  </gazebo>

  <transmission name="right_wheel_trans">
    <type>transmission_interface/SimpleTransmission</type>
    <joint name="large_right_wheel_joint">
      <hardwareInterface>EffortJointInterface</hardwareInterface>
    </joint>   
    <actuator name="motor_rightwheel">
      <hardwareInterface>EffortJointInterface</hardwareInterface>
      <mechanicalReduction>1</mechanicalReduction>
    </actuator>
  </transmission>

  <transmission name="left_wheel_trans">
    <type>transmission_interface/SimpleTransmission</type>
    <joint name="large_left_wheel_joint">
      <hardwareInterface>EffortJointInterface</hardwareInterface>
    </joint>
    <actuator name="motor_leftwheel">
      <hardwareInterface>EffortJointInterface</hardwareInterface>
      <mechanicalReduction>1</mechanicalReduction>
    </actuator>
  </transmission>


</robot>
